# 背景知识
ctx.throw([status], [msg], [properties])
例子
```js
ctx.throw(400);
ctx.throw(400, 'name required');

// 根据需要将 properties 对象传递到错误中
// 开发者利用这个后台可以看到这个property属性，从而知道一些信息，如用户的信息
ctx.throw(400, 'name required', { user: user });
```

# 正文
1. 默认情况下，将所有错误输出到 stderr，除非 app.silent 为 true
2. 当 err.status 是 404 或 err.expose 是 true 时默认错误处理程序也不会输出错误
3. 要执行自定义错误处理逻辑您可以添加一个 “error” 事件侦听器



  ```js
  app.on('error', err => {
    log.error('server error', err)
  });
  ```

# app.on 自动义错误输出到控制台
添加一个 “error” 事件侦听器
```js
app.on('error', (err, ctx) => {
  // 二者选1，都是自定义输出到控制台
  // console.error('server error', err);
  console.error('server error', err, ctx);
});

app.use(async ctx => {
  // 自定义抛出一个错误
    ctx.throw(500, '出错啦~~~~~');
    ctx.body = 'hello world';
});
```

# try catch 立刻捕捉错误
```js
app.use(async ctx => {
  // 自定义抛出一个错误
  try {
    ctx.throw(500, '出错啦~~~~~');
    ctx.body = 'hello world';
  } catch (err) {
    console.log(err);
    ctx.body = `error happen ----> custom\n${err.message}`;
  }
});
```

# 级联捕捉错误
```js
// 写在较前面
app.use(async (ctx, next) => {
  try {
    await next();
  } catch (err) {
    console.log(err);
    ctx.body = `error happen ----> custom
    \nstatus: ${err.status}\tmessage: ${err.message}`;
  }
});

app.use(async ctx => {
  // 自定义抛出一个错误
  ctx.throw(500, '出错啦~~~~~');
  ctx.body = 'hello world';
});

```